<?xml version="1.0"?>
<robot name='bicycle'>

    <!--########## link ##########-->
    <!--<link name="base">
    <visual>
      <geometry>
        <box size="30 0.03 0.03"/>
      </geometry>
      <origin xyz="0 0 0"/>
      <material name="green">
        <color rgba="0 0.8 .8 1"/>
      </material>
    </visual>
    <inertial>
      <mass value="0"/>
      <inertia ixx="1.0" ixy="0.0" ixz="0.0" iyy="1.0" iyz="0.0" izz="1.0"/>
    </inertial>
  </link>-->

    <link name='main_frame'>
        <inertial>
            <mass value="20"/>
            <inertia ixx="10" ixy="0.0" ixz="0.0" iyy="2" iyz="0.0" izz="11"/>
            <origin xyz="0 0.53 0.37" rpy="0 0 0"/>
        </inertial>
        <visual name='visual'>
            <origin xyz="0 0.53 0.37" rpy="0 0 0"/>
            <geometry>
                <mesh filename="meshes/main_frame_centered.stl" scale="0.17 0.17 0.17"/>
            </geometry>
            <material name="black">
                <color rgba="1.0 1.0 1.0 1"/>
            </material>
        </visual>
        <collision>
            <origin xyz="0 0.53 0.37" rpy="0 0 0"/>
            <geometry>
                <mesh filename="meshes/main_frame_centered.stl" scale="0.17 0.17 0.17"/>
            </geometry>
            <surface>
                <friction>
                    <ode>
                        <mu>1</mu>
                        <mu2>1</mu2>
                        <fdir1>0 0 0</fdir1>
                        <slip1>0</slip1>
                        <slip2>0</slip2>
                    </ode>
                    <torsional>
                        <coefficient>1</coefficient>
                        <patch_radius>0</patch_radius>
                        <surface_radius>0</surface_radius>
                        <use_patch_radius>1</use_patch_radius>
                        <ode>
                            <slip>0</slip>
                        </ode>
                    </torsional>
                </friction>
                <bounce>
                    <restitution_coefficient>0</restitution_coefficient>
                    <threshold>1e+06</threshold>
                </bounce>
                <contact>
                    <collide_without_contact>0</collide_without_contact>
                    <collide_without_contact_bitmask>1</collide_without_contact_bitmask>
                    <collide_bitmask>1</collide_bitmask>
                    <ode>
                        <soft_cfm>0</soft_cfm>
                        <soft_erp>0.2</soft_erp>
                        <kp>1e+13</kp>
                        <kd>1</kd>
                        <max_vel>0.01</max_vel>
                        <min_depth>0</min_depth>
                    </ode>
                    <bullet>
                        <split_impulse>1</split_impulse>
                        <split_impulse_penetration_threshold>-0.01</split_impulse_penetration_threshold>
                        <soft_cfm>0</soft_cfm>
                        <soft_erp>0.2</soft_erp>
                        <kp>1e+13</kp>
                        <kd>1</kd>
                    </bullet>
                </contact>
            </surface>
        </collision>
    </link>

    <link name='saddle'>
        <inertial>
            <mass value="0.2"/>
            <inertia ixx="0.16667" ixy="0.0" ixz="0.0" iyy="0.16667" iyz="0.0" izz="0.16667"/>
        </inertial>
        <visual name='visual'>
            <origin xyz="0 0 0" rpy="0 0 0"/>
            <geometry>
                <mesh filename="meshes/saddle_centered.stl" scale="0.1 0.1 0.1"/>
            </geometry>
            <material name="black">
                <color rgba="1.0 1.0 1.0 1"/>
            </material>
        </visual>
        <collision>
            <origin xyz="0 0 0" rpy="0 0 0"/>
            <geometry>
                <mesh filename="meshes/saddle_centered.stl" scale="0.1 0.1 0.1"/>
            </geometry>
            <surface>
                <friction>
                    <ode>
                        <mu>1</mu>
                        <mu2>1</mu2>
                        <fdir1>0 0 0</fdir1>
                        <slip1>0</slip1>
                        <slip2>0</slip2>
                    </ode>
                    <torsional>
                        <coefficient>1</coefficient>
                        <patch_radius>0</patch_radius>
                        <surface_radius>0</surface_radius>
                        <use_patch_radius>1</use_patch_radius>
                        <ode>
                            <slip>0</slip>
                        </ode>
                    </torsional>
                </friction>
                <bounce>
                    <restitution_coefficient>0</restitution_coefficient>
                    <threshold>1e+06</threshold>
                </bounce>
                <contact>
                    <collide_without_contact>0</collide_without_contact>
                    <collide_without_contact_bitmask>1</collide_without_contact_bitmask>
                    <collide_bitmask>1</collide_bitmask>
                    <ode>
                        <soft_cfm>0</soft_cfm>
                        <soft_erp>0.2</soft_erp>
                        <kp>1e+13</kp>
                        <kd>1</kd>
                        <max_vel>0.01</max_vel>
                        <min_depth>0</min_depth>
                    </ode>
                    <bullet>
                        <split_impulse>1</split_impulse>
                        <split_impulse_penetration_threshold>-0.01</split_impulse_penetration_threshold>
                        <soft_cfm>0</soft_cfm>
                        <soft_erp>0.2</soft_erp>
                        <kp>1e+13</kp>
                        <kd>1</kd>
                    </bullet>
                </contact>
            </surface>
        </collision>
    </link>

    <link name='handlebar'>
        <inertial>
            <mass value="1"/>
            <inertia ixx="0.06" ixy="0.0" ixz="0.0" iyy="0.06" iyz="0.0" izz="0.06"/>
            <origin xyz="0 0 0" rpy="0 0 0"/>
        </inertial>
        <visual name='visual'>
            <origin xyz="0 0 0" rpy="0 0 0"/>
            <geometry>
                <mesh filename="meshes/handlebar_centered.stl" scale="0.2 0.2 0.2"/>
            </geometry>
            <material name="black">
                <color rgba="1.0 1.0 1.0 1"/>
            </material>
        </visual>
        <collision>
            <origin xyz="0 0 0" rpy="0 0 0"/>
            <geometry>
                <mesh filename="meshes/handlebar_centered.stl" scale="0.2 0.2 0.2"/>
            </geometry>
            <surface>
                <friction>
                    <ode>
                        <mu>1</mu>
                        <mu2>1</mu2>
                        <fdir1>0 0 0</fdir1>
                        <slip1>0</slip1>
                        <slip2>0</slip2>
                    </ode>
                    <torsional>
                        <coefficient>1</coefficient>
                        <patch_radius>0</patch_radius>
                        <surface_radius>0</surface_radius>
                        <use_patch_radius>1</use_patch_radius>
                        <ode>
                            <slip>0</slip>
                        </ode>
                    </torsional>
                </friction>
                <bounce>
                    <restitution_coefficient>0</restitution_coefficient>
                    <threshold>1e+06</threshold>
                </bounce>
                <contact>
                    <collide_without_contact>0</collide_without_contact>
                    <collide_without_contact_bitmask>1</collide_without_contact_bitmask>
                    <collide_bitmask>1</collide_bitmask>
                    <ode>
                        <soft_cfm>0</soft_cfm>
                        <soft_erp>0.2</soft_erp>
                        <kp>1e+13</kp>
                        <kd>1</kd>
                        <max_vel>0.01</max_vel>
                        <min_depth>0</min_depth>
                    </ode>
                    <bullet>
                        <split_impulse>1</split_impulse>
                        <split_impulse_penetration_threshold>-0.01</split_impulse_penetration_threshold>
                        <soft_cfm>0</soft_cfm>
                        <soft_erp>0.2</soft_erp>
                        <kp>1e+13</kp>
                        <kd>1</kd>
                    </bullet>
                </contact>
            </surface>
        </collision>
    </link>

    <link name='link_handle'>
        <inertial>
            <mass value="1"/>
            <inertia ixx="0.06" ixy="0.0" ixz="0.0" iyy="0.06" iyz="0.0" izz="0.06"/>
            <origin xyz="0 0 0" rpy="0 0 0"/>
        </inertial>
        <visual name='visual'>
            <origin xyz="0 0 0" rpy="0 0 0"/>
            <geometry>
                <mesh filename="meshes/link_handle_centered.stl" scale="0.1 0.1 0.1"/>
            </geometry>
            <material name="black">
                <color rgba="1.0 1.0 1.0 1"/>
            </material>
        </visual>
        <collision>
            <origin xyz="0 0 0" rpy="0 0 0"/>
            <geometry>
                <mesh filename="meshes/link_handle_centered.stl" scale="0.1 0.1 0.1"/>
            </geometry>
            <surface>
                <friction>
                    <ode>
                        <mu>1</mu>
                        <mu2>1</mu2>
                        <fdir1>0 0 0</fdir1>
                        <slip1>0</slip1>
                        <slip2>0</slip2>
                    </ode>
                    <torsional>
                        <coefficient>1</coefficient>
                        <patch_radius>0</patch_radius>
                        <surface_radius>0</surface_radius>
                        <use_patch_radius>1</use_patch_radius>
                        <ode>
                            <slip>0</slip>
                        </ode>
                    </torsional>
                </friction>
                <bounce>
                    <restitution_coefficient>0</restitution_coefficient>
                    <threshold>1e+06</threshold>
                </bounce>
                <contact>
                    <collide_without_contact>0</collide_without_contact>
                    <collide_without_contact_bitmask>1</collide_without_contact_bitmask>
                    <collide_bitmask>1</collide_bitmask>
                    <ode>
                        <soft_cfm>0</soft_cfm>
                        <soft_erp>0.2</soft_erp>
                        <kp>1e+13</kp>
                        <kd>1</kd>
                        <max_vel>0.01</max_vel>
                        <min_depth>0</min_depth>
                    </ode>
                    <bullet>
                        <split_impulse>1</split_impulse>
                        <split_impulse_penetration_threshold>-0.01</split_impulse_penetration_threshold>
                        <soft_cfm>0</soft_cfm>
                        <soft_erp>0.2</soft_erp>
                        <kp>1e+13</kp>
                        <kd>1</kd>
                    </bullet>
                </contact>
            </surface>
        </collision>
    </link>

    <link name='link_wheel'>
        <inertial>
            <mass value="3"/>
            <inertia ixx="0.06" ixy="0.0" ixz="0.00756" iyy="0.06" iyz="0.0" izz="0.06"/>
            <origin xyz="0 0 0" rpy="0 0 0"/>
        </inertial>
        <visual name='visual'>
            <origin xyz="0 0 0" rpy="0 0 0"/>
            <geometry>
                <mesh filename="meshes/link_wheel_centered.stl" scale="0.11 0.11 0.11"/>
            </geometry>
            <material name="black">
                <color rgba="1.0 1.0 1.0 1"/>
            </material>
        </visual>
        <collision>
            <origin xyz="0 0 0" rpy="0 0 0"/>
            <geometry>
                <mesh filename="meshes/link_wheel_centered.stl" scale="0.11 0.11 0.11"/>
            </geometry>
            <surface>
                <friction>
                    <ode>
                        <mu>1</mu>
                        <mu2>1</mu2>
                        <fdir1>0 0 0</fdir1>
                        <slip1>0</slip1>
                        <slip2>0</slip2>
                    </ode>
                    <torsional>
                        <coefficient>1</coefficient>
                        <patch_radius>0</patch_radius>
                        <surface_radius>0</surface_radius>
                        <use_patch_radius>1</use_patch_radius>
                        <ode>
                            <slip>0</slip>
                        </ode>
                    </torsional>
                </friction>
                <bounce>
                    <restitution_coefficient>0</restitution_coefficient>
                    <threshold>1e+06</threshold>
                </bounce>
                <contact>
                    <collide_without_contact>0</collide_without_contact>
                    <collide_without_contact_bitmask>1</collide_without_contact_bitmask>
                    <collide_bitmask>1</collide_bitmask>
                    <ode>
                        <soft_cfm>0</soft_cfm>
                        <soft_erp>0.2</soft_erp>
                        <kp>1e+13</kp>
                        <kd>1</kd>
                        <max_vel>0.01</max_vel>
                        <min_depth>0</min_depth>
                    </ode>
                    <bullet>
                        <split_impulse>1</split_impulse>
                        <split_impulse_penetration_threshold>-0.01</split_impulse_penetration_threshold>
                        <soft_cfm>0</soft_cfm>
                        <soft_erp>0.2</soft_erp>
                        <kp>1e+13</kp>
                        <kd>1</kd>
                    </bullet>
                </contact>
            </surface>
        </collision>
    </link>

    <link name='wheel_front'>
        <inertial>
            <mass value="3"/>
            <inertia ixx="0.1405" ixy="0.0" ixz="0.0" iyy="0.1405" iyz="0.0" izz="0.14"/>
            <origin xyz="0 0 0" rpy="0 0 0"/>
        </inertial>
        <visual name='visual'>
            <origin xyz="0 0 0" rpy="0 0 0"/>
            <geometry>
                <mesh filename="meshes/wheel_full_centered.stl" scale="0.31 0.11 0.11"/>
                <!--<cylinder length="0.1" radius="0.37"/>-->
            </geometry>
            <material name="black">
                <color rgba="1.0 1.0 1.0 1"/>
            </material>
        </visual>
        <collision>
            <origin xyz="0 0 0" rpy="0 0 0"/>
            <geometry>
                <mesh filename="meshes/wheel_full_centered.stl" scale="0.31 0.11 0.11"/>
                <!--<cylinder length="0.1" radius="0.37"/>-->
            </geometry>
            <surface>
                <friction>
                    <ode>
                        <mu>1</mu>
                        <mu2>1</mu2>
                        <fdir1>0 0 0</fdir1>
                        <slip1>0</slip1>
                        <slip2>0</slip2>
                    </ode>
                    <torsional>
                        <coefficient>1</coefficient>
                        <patch_radius>0</patch_radius>
                        <surface_radius>0</surface_radius>
                        <use_patch_radius>1</use_patch_radius>
                        <ode>
                            <slip>0</slip>
                        </ode>
                    </torsional>
                </friction>
                <bounce>
                    <restitution_coefficient>0</restitution_coefficient>
                    <threshold>1e+06</threshold>
                </bounce>
                <contact>
                    <collide_without_contact>0</collide_without_contact>
                    <collide_without_contact_bitmask>1</collide_without_contact_bitmask>
                    <collide_bitmask>1</collide_bitmask>
                    <ode>
                        <soft_cfm>0</soft_cfm>
                        <soft_erp>0.2</soft_erp>
                        <kp>1e+13</kp>
                        <kd>1</kd>
                        <max_vel>0.01</max_vel>
                        <min_depth>0</min_depth>
                    </ode>
                    <bullet>
                        <split_impulse>1</split_impulse>
                        <split_impulse_penetration_threshold>-0.01</split_impulse_penetration_threshold>
                        <soft_cfm>0</soft_cfm>
                        <soft_erp>0.2</soft_erp>
                        <kp>1e+13</kp>
                        <kd>1</kd>
                    </bullet>
                </contact>
            </surface>
        </collision>
    </link>

    <link name='wheel_rear'>
        <inertial>
            <mass value="7"/>
            <inertia ixx="0.1405" ixy="0.0" ixz="0.0" iyy="0.1405" iyz="0.0" izz="0.14"/>
            <origin xyz="0 0 0" rpy="0 0 0"/>
        </inertial>
        <visual name='visual'>
            <origin xyz="0 0 0" rpy="0 0 0"/>
            <geometry>
                <mesh filename="meshes/wheel_full_centered.stl" scale="0.31 0.11 0.11"/>
                <!--<cylinder length="0.1" radius="0.37"/>-->
            </geometry>
            <material name="black">
                <color rgba="1.0 1.0 1.0 1"/>
            </material>
        </visual>
        <collision>
            <origin xyz="0 0 0" rpy="0 0 0"/>
            <geometry>
                <mesh filename="meshes/wheel_full_centered.stl" scale="0.31 0.11 0.11"/>
                <!--<cylinder length="0.1" radius="0.37"/>-->
            </geometry>
            <surface>
                <friction>
                    <ode>
                        <mu>1</mu>
                        <mu2>1</mu2>
                        <fdir1>0 0 0</fdir1>
                        <slip1>0</slip1>
                        <slip2>0</slip2>
                    </ode>
                    <torsional>
                        <coefficient>1</coefficient>
                        <patch_radius>0</patch_radius>
                        <surface_radius>0</surface_radius>
                        <use_patch_radius>1</use_patch_radius>
                        <ode>
                            <slip>0</slip>
                        </ode>
                    </torsional>
                </friction>
                <bounce>
                    <restitution_coefficient>0</restitution_coefficient>
                    <threshold>1e+06</threshold>
                </bounce>
                <contact>
                    <collide_without_contact>0</collide_without_contact>
                    <collide_without_contact_bitmask>1</collide_without_contact_bitmask>
                    <collide_bitmask>1</collide_bitmask>
                    <ode>
                        <soft_cfm>0</soft_cfm>
                        <soft_erp>0.2</soft_erp>
                        <kp>1e+13</kp>
                        <kd>1</kd>
                        <max_vel>0.01</max_vel>
                        <min_depth>0</min_depth>
                    </ode>
                    <bullet>
                        <split_impulse>1</split_impulse>
                        <split_impulse_penetration_threshold>-0.01</split_impulse_penetration_threshold>
                        <soft_cfm>0</soft_cfm>
                        <soft_erp>0.2</soft_erp>
                        <kp>1e+13</kp>
                        <kd>1</kd>
                    </bullet>
                </contact>
            </surface>
        </collision>
    </link>

    <!--########## joint ##########-->
    <joint name='main_frame_wheel_rear' type='continuous'>
        <parent link="main_frame"/>
        <child link="wheel_rear"/>
        <origin xyz="0 0 0.37" rpy="0 0 0"/>
        <axis xyz="-1 0 0"/>
    </joint>

    <joint name='main_frame_link_handle' type='revolute'>
        <parent link="main_frame"/>
        <child link="link_wheel"/>
        <origin xyz="0 1.10 0.80" rpy="-0.2 0 3.1415"/>
        <axis xyz="0 0 1"/>
        <limit lower="-1.5708" upper="1.5708" effort="-1" velocity="-1"/>
    </joint>

    <joint name='link_wheel_wheel_front' type='continuous'>
        <parent link="link_wheel"/>
        <child link="wheel_front"/>
        <origin xyz="0 0 -0.45" rpy="-0.26 0 3.1415"/>
        <axis xyz="-1 0 0"/>
    </joint>

    <joint name='main_frame_saddle' type='fixed'>
        <parent link="main_frame"/>
        <child link="saddle"/>
        <origin xyz="0 0.4 0.81" rpy="-0.2 0 3.1415"/>
    </joint>

    <joint name='link_handle_handlebar' type='fixed'>
        <parent link="link_handle"/>
        <child link="handlebar"/>
        <origin xyz="0 -0.04 0" rpy="-0.3 0 3.1415"/>
    </joint>

    <joint name='link_handle_link_wheel' type='fixed'>
        <parent link="link_wheel"/>
        <child link="link_handle"/>
        <origin xyz="0 -0.055 0.13" rpy="0.36 0 0"/>
    </joint>

    <!--<joint name='base' type='fixed'>
        <parent link="base"/>
        <child link="main_frame"/>
        <origin xyz="0 0 0" rpy="0 0 0"/>
    </joint>-->
</robot>